Workbook

Sheet Census Data
A1: Last updated | B1: State | C1: Type of Data | D1: Description | E1: Exists | F1: Digitized | G1: Public | H1: Free | I1: Online | J1: Machine readable | K1: Available in bulk | L1: No restrictions | M1: Up-to-date | N1: In the state repository | O1: Verifiable | P1: Complete | Q1: Link | R1: Comments | S1: Score | T1: Grade
A2: 42349 | B2: Alabama | C2: Address Points | D2: =IF(NOT(ISBLANK(C2)), VLOOKUP(C2,'Dataset Descriptions'!$A$2:$B$10, 2, FALSE), "") -> The geographic coordinates for physical addresses. | E2: unsure | F2: unsure | G2: unsure | H2: unsure | I2: no | J2: unsure | K2: no | L2: unsure | M2: unsure | N2: no | O2: no | P2: unsure | S2: =IF(NOT(ISBLANK(E2)), ROUND(((IF(E2="yes",1,0)*'Grading Scale'!E$2)+(IF(F2="yes",1,0)*'Grading Scale'!E$3)+(IF(G2="yes",1,0)*'Grading Scale'!E$4)+(IF(H2="yes",1,0)*'Grading Scale'!E$5)+(IF(I2="yes",1,0)*'Grading Scale'!E$6)+(IF(J2="yes",1,0)*'Grading Scale'!E$7)+(IF(K2="yes",1,0)*'Grading Scale'!E$8)+(IF(L2="yes",1,0)*'Grading Scale'!E$9)+(IF(M2="yes",1,0)*'Grading Scale'!E$10)+(IF(N2="yes",1,0)*'Grading Scale'!E$11)+(IF(O2="yes",1,0)*'Grading Scale'!E$12)+(IF(P2="yes",1,0)*'Grading Scale'!E$13))/'Grading Scale'!E$14*100,0), "") -> 0 | T2: =IF(ISNUMBER(S2),VLOOKUP(S2,'Grading Scale'!$A$2:$B$14, 2), "") -> F
A3: 42459 | B3: Alabama | C3: Checkbook | D3: =IF(NOT(ISBLANK(C3)), VLOOKUP(C3,'Dataset Descriptions'!$A$2:$B$10, 2, FALSE), "") -> Transaction-level, per-agency spending records. | E3: yes | F3: yes | G3: yes | H3: yes | I3: yes | J3: no | K3: no | L3: yes | M3: no | N3: no | O3: no | P3: no | Q3: http://open.alabama.gov/spending_checkbook.aspx | R3: At the time that it was surveyed, the data had not been updated for over two months. Does not include a description of the purpose of the expenditure. The results of queries can be exported as Excel files, but so few record-level results can be exported at one time that this hardly quaifies as offering machine-readable data. | S3: =IF(NOT(ISBLANK(E3)), ROUND(((IF(E3="yes",1,0)*'Grading Scale'!E$2)+(IF(F3="yes",1,0)*'Grading Scale'!E$3)+(IF(G3="yes",1,0)*'Grading Scale'!E$4)+(IF(H3="yes",1,0)*'Grading Scale'!E$5)+(IF(I3="yes",1,0)*'Grading Scale'!E$6)+(IF(J3="yes",1,0)*'Grading Scale'!E$7)+(IF(K3="yes",1,0)*'Grading Scale'!E$8)+(IF(L3="yes",1,0)*'Grading Scale'!E$9)+(IF(M3="yes",1,0)*'Grading Scale'!E$10)+(IF(N3="yes",1,0)*'Grading Scale'!E$11)+(IF(O3="yes",1,0)*'Grading Scale'!E$12)+(IF(P3="yes",1,0)*'Grading Scale'!E$13))/'Grading Scale'!E$14*100,0), "") -> 35 | T3: =IF(ISNUMBER(S3),VLOOKUP(S3,'Grading Scale'!$A$2:$B$14, 2), "") -> F
A4: 42349 | B4: Alabama | C4: Companies | D4: =IF(NOT(ISBLANK(C4)), VLOOKUP(C4,'Dataset Descriptions'!$A$2:$B$10, 2, FALSE), "") -> The register of all corporations that exist in the state. | E4: yes | F4: yes | G4: yes | H4: yes | I4: yes | J4: no | K4: no | L4: no | M4: no | N4: no | O4: no | P4: yes | Q4: http://arc-sos.state.al.us/CGI/CORPNAME.MBR/INPUT | R4: At the time that it was surveyed, the data was 6 weeks out of date. | S4: =IF(NOT(ISBLANK(E4)), ROUND(((IF(E4="yes",1,0)*'Grading Scale'!E$2)+(IF(F4="yes",1,0)*'Grading Scale'!E$3)+(IF(G4="yes",1,0)*'Grading Scale'!E$4)+(IF(H4="yes",1,0)*'Grading Scale'!E$5)+(IF(I4="yes",1,0)*'Grading Scale'!E$6)+(IF(J4="yes",1,0)*'Grading Scale'!E$7)+(IF(K4="yes",1,0)*'Grading Scale'!E$8)+(IF(L4="yes",1,0)*'Grading Scale'!E$9)+(IF(M4="yes",1,0)*'Grading Scale'!E$10)+(IF(N4="yes",1,0)*'Grading Scale'!E$11)+(IF(O4="yes",1,0)*'Grading Scale'!E$12)+(IF(P4="yes",1,0)*'Grading Scale'!E$13))/'Grading Scale'!E$14*100,0), "") -> 35 | T4: =IF(ISNUMBER(S4),VLOOKUP(S4,'Grading Scale'!$A$2:$B$14, 2), "") -> F
A5: 42349 | B5: Alabama | C5: Incarceration | D5: =IF(NOT(ISBLANK(C5)), VLOOKUP(C5,'Dataset Descriptions'!$A$2:$B$10, 2, FALSE), "") -> Per-facility inmate population records. | E5: yes | F5: yes | G5: yes | H5: yes | I5: yes | J5: no | K5: yes | L5: no | M5: no | N5: no | O5: no | P5: yes | Q5: http://www.doc.state.al.us/StatReports.aspx | R5: At the time that it was surveyed, data was over two months old. | S5: =IF(NOT(ISBLANK(E5)), ROUND(((IF(E5="yes",1,0)*'Grading Scale'!E$2)+(IF(F5="yes",1,0)*'Grading Scale'!E$3)+(IF(G5="yes",1,0)*'Grading Scale'!E$4)+(IF(H5="yes",1,0)*'Grading Scale'!E$5)+(IF(I5="yes",1,0)*'Grading Scale'!E$6)+(IF(J5="yes",1,0)*'Grading Scale'!E$7)+(IF(K5="yes",1,0)*'Grading Scale'!E$8)+(IF(L5="yes",1,0)*'Grading Scale'!E$9)+(IF(M5="yes",1,0)*'Grading Scale'!E$10)+(IF(N5="yes",1,0)*'Grading Scale'!E$11)+(IF(O5="yes",1,0)*'Grading Scale'!E$12)+(IF(P5="yes",1,0)*'Grading Scale'!E$13))/'Grading Scale'!E$14*100,0), "") -> 40 | T5: =IF(ISNUMBER(S5),VLOOKUP(S5,'Grading Scale'!$A$2:$B$14, 2), "") -> F
A6: 42349 | B6: Alabama | C6: Legislation | D6: =IF(NOT(ISBLANK(C6)), VLOOKUP(C6,'Dataset Descriptions'!$A$2:$B$10, 2, FALSE), "") -> Bills before the legislature, and the legislators that comprise it. | E6: yes | F6: yes | G6: yes | H6: yes | I6: yes | J6: no | K6: no | L6: yes | M6: unsure | N6: no | O6: no | P6: unsure | Q6: http://www.legislature.state.al.us/ | R6: This is surely the worst legislative website in the nation. It is such a mess that it is difficult to assess meaningfully. | S6: =IF(NOT(ISBLANK(E6)), ROUND(((IF(E6="yes",1,0)*'Grading Scale'!E$2)+(IF(F6="yes",1,0)*'Grading Scale'!E$3)+(IF(G6="yes",1,0)*'Grading Scale'!E$4)+(IF(H6="yes",1,0)*'Grading Scale'!E$5)+(IF(I6="yes",1,0)*'Grading Scale'!E$6)+(IF(J6="yes",1,0)*'Grading Scale'!E$7)+(IF(K6="yes",1,0)*'Grading Scale'!E$8)+(IF(L6="yes",1,0)*'Grading Scale'!E$9)+(IF(M6="yes",1,0)*'Grading Scale'!E$10)+(IF(N6="yes",1,0)*'Grading Scale'!E$11)+(IF(O6="yes",1,0)*'Grading Scale'!E$12)+(IF(P6="yes",1,0)*'Grading Scale'!E$13))/'Grading Scale'!E$14*100,0), "") -> 35 | T6: =IF(ISNUMBER(S6),VLOOKUP(S6,'Grading Scale'!$A$2:$B$14, 2), "") -> F
A7: 42349 | B7: Alabama | C7: Population Projections | D7: =IF(NOT(ISBLANK(C7)), VLOOKUP(C7,'Dataset Descriptions'!$A$2:$B$10, 2, FALSE), "") -> Forecasts of municipal-level changes in population over coming years. | E7: yes | F7: yes | G7: yes | H7: yes | I7: yes | J7: yes | K7: no | L7: yes | M7: yes | N7: no | O7: no | P7: no | Q7: http://cber.cba.ua.edu/edata/est_prj.html | R7: Lacks GNIS IDs for localities. | S7: =IF(NOT(ISBLANK(E7)), ROUND(((IF(E7="yes",1,0)*'Grading Scale'!E$2)+(IF(F7="yes",1,0)*'Grading Scale'!E$3)+(IF(G7="yes",1,0)*'Grading Scale'!E$4)+(IF(H7="yes",1,0)*'Grading Scale'!E$5)+(IF(I7="yes",1,0)*'Grading Scale'!E$6)+(IF(J7="yes",1,0)*'Grading Scale'!E$7)+(IF(K7="yes",1,0)*'Grading Scale'!E$8)+(IF(L7="yes",1,0)*'Grading Scale'!E$9)+(IF(M7="yes",1,0)*'Grading Scale'!E$10)+(IF(N7="yes",1,0)*'Grading Scale'!E$11)+(IF(O7="yes",1,0)*'Grading Scale'!E$12)+(IF(P7="yes",1,0)*'Grading Scale'!E$13))/'Grading Scale'!E$14*100,0), "") -> 80 | T7: =IF(ISNUMBER(S7),VLOOKUP(S7,'Grading Scale'!$A$2:$B$14, 2), "") -> B−
A8: 42349 | B8: Alabama | C8: Real Estate | D8: =IF(NOT(ISBLANK(C8)), VLOOKUP(C8,'Dataset Descriptions'!$A$2:$B$10, 2, FALSE), "") -> State-owned land and buildings. | E8: yes | F8: yes | G8: yes | H8: yes | I8: yes | J8: no | K8: no | L8: no | M8: unsure | N8: no | O8: no | P8: no | Q8: http://open.alabama.gov/state_properties.aspx | R8: The use of each facility is not specified. The data is split between three unrelated websites (one for leased buildings, one for owned buildings, and one for land). Dates are not included for most records, so it is difficult to determine if the data is up-to-date. | S8: =IF(NOT(ISBLANK(E8)), ROUND(((IF(E8="yes",1,0)*'Grading Scale'!E$2)+(IF(F8="yes",1,0)*'Grading Scale'!E$3)+(IF(G8="yes",1,0)*'Grading Scale'!E$4)+(IF(H8="yes",1,0)*'Grading Scale'!E$5)+(IF(I8="yes",1,0)*'Grading Scale'!E$6)+(IF(J8="yes",1,0)*'Grading Scale'!E$7)+(IF(K8="yes",1,0)*'Grading Scale'!E$8)+(IF(L8="yes",1,0)*'Grading Scale'!E$9)+(IF(M8="yes",1,0)*'Grading Scale'!E$10)+(IF(N8="yes",1,0)*'Grading Scale'!E$11)+(IF(O8="yes",1,0)*'Grading Scale'!E$12)+(IF(P8="yes",1,0)*'Grading Scale'!E$13))/'Grading Scale'!E$14*100,0), "") -> 30 | T8: =IF(ISNUMBER(S8),VLOOKUP(S8,'Grading Scale'!$A$2:$B$14, 2), "") -> F
A9: 42349 | B9: Alabama | C9: Restaurant Inspections | D9: =IF(NOT(ISBLANK(C9)), VLOOKUP(C9,'Dataset Descriptions'!$A$2:$B$10, 2, FALSE), "") -> Health inspections of establishments that serve food to the public. | E9: yes | F9: yes | G9: yes | H9: yes | I9: yes | J9: no | K9: no | L9: yes | M9: yes | N9: no | O9: no | P9: no | Q9: http://foodscores.state.al.us/ | R9: Does not include unique identifiers or the outcome of inspections (passed, failed, etc.) | S9: =IF(NOT(ISBLANK(E9)), ROUND(((IF(E9="yes",1,0)*'Grading Scale'!E$2)+(IF(F9="yes",1,0)*'Grading Scale'!E$3)+(IF(G9="yes",1,0)*'Grading Scale'!E$4)+(IF(H9="yes",1,0)*'Grading Scale'!E$5)+(IF(I9="yes",1,0)*'Grading Scale'!E$6)+(IF(J9="yes",1,0)*'Grading Scale'!E$7)+(IF(K9="yes",1,0)*'Grading Scale'!E$8)+(IF(L9="yes",1,0)*'Grading Scale'!E$9)+(IF(M9="yes",1,0)*'Grading Scale'!E$10)+(IF(N9="yes",1,0)*'Grading Scale'!E$11)+(IF(O9="yes",1,0)*'Grading Scale'!E$12)+(IF(P9="yes",1,0)*'Grading Scale'!E$13))/'Grading Scale'!E$14*100,0), "") -> 40 | T9: =IF(ISNUMBER(S9),VLOOKUP(S9,'Grading Scale'!$A$2:$B$14, 2), "") -> F
A10: 42349 | B10: Alabama | C10: Vehicle Crashes | D10: =IF(NOT(ISBLANK(C10)), VLOOKUP(C10,'Dataset Descriptions'!$A$2:$B$10, 2, FALSE), "") -> Incident-level reportable motor vehicle crash records. | E10: yes | F10: yes | G10: yes | H10: yes | I10: yes | J10: no | K10: no | L10: yes | M10: no | N10: no | O10: no | P10: no | Q10: http://www.dot.state.al.us/mcrweb/frm/Crash_Facts.pdf | R10: This is a PDF from 2012, containing statistics, not raw data. This is the best data source that could be identified. | S10: =IF(NOT(ISBLANK(E10)), ROUND(((IF(E10="yes",1,0)*'Grading Scale'!E$2)+(IF(F10="yes",1,0)*'Grading Scale'!E$3)+(IF(G10="yes",1,0)*'Grading Scale'!E$4)+(IF(H10="yes",1,0)*'Grading Scale'!E$5)+(IF(I10="yes",1,0)*'Grading Scale'!E$6)+(IF(J10="yes",1,0)*'Grading Scale'!E$7)+(IF(K10="yes",1,0)*'Grading Scale'!E$8)+(IF(L10="yes",1,0)*'Grading Scale'!E$9)+(IF(M10="yes",1,0)*'Grading Scale'!E$10)+(IF(N10="yes",1,0)*'Grading Scale'!E$11)+(IF(O10="yes",1,0)*'Grading Scale'!E$12)+(IF(P10="yes",1,0)*'Grading Scale'!E$13))/'Grading Scale'!E$14*100,0), "") -> 35 | T10: =IF(ISNUMBER(S10),VLOOKUP(S10,'Grading Scale'!$A$2:$B$14, 2), "") -> F
A11: 42408 | B11: Alaska | C11: Address Points | D11: =IF(NOT(ISBLANK(C11)), VLOOKUP(C11,'Dataset Descriptions'!$A$2:$B$10, 2, FALSE), "") -> The geographic coordinates for physical addresses. | E11: unsure | F11: unsure | G11: unsure | H11: unsure | I11: no | J11: unsure | K11: unsure | L11: unsure | M11: unsure | N11: no | O11: unsure | P11: unsure | S11: =IF(NOT(ISBLANK(E11)), ROUND(((IF(E11="yes",1,0)*'Grading Scale'!E$2)+(IF(F11="yes",1,0)*'Grading Scale'!E$3)+(IF(G11="yes",1,0)*'Grading Scale'!E$4)+(IF(H11="yes",1,0)*'Grading Scale'!E$5)+(IF(I11="yes",1,0)*'Grading Scale'!E$6)+(IF(J11="yes",1,0)*'Grading Scale'!E$7)+(IF(K11="yes",1,0)*'Grading Scale'!E$8)+(IF(L11="yes",1,0)*'Grading Scale'!E$9)+(IF(M11="yes",1,0)*'Grading Scale'!E$10)+(IF(N11="yes",1,0)*'Grading Scale'!E$11)+(IF(O11="yes",1,0)*'Grading Scale'!E$12)+(IF(P11="yes",1,0)*'Grading Scale'!E$13))/'Grading Scale'!E$14*100,0), "") -> 0 | T11: =IF(ISNUMBER(S11),VLOOKUP(S11,'Grading Scale'!$A$2:$B$14, 2), "") -> F
A12: 42408 | B12: Alaska | C12: Checkbook | D12: =IF(NOT(ISBLANK(C12)), VLOOKUP(C12,'Dataset Descriptions'!$A$2:$B$10, 2, FALSE), "") -> Transaction-level, per-agency spending records. | E12: yes | F12: yes | G12: yes | H12: yes | I12: yes | J12: yes | K12: yes | L12: yes | M12: yes | N12: no | O12: no | P12: no | Q12: http://doa.alaska.gov/dof/reports/ckbkonline_reports.html | R12: Incomplete, because transaction records lack a description of their purpose and a check or voucher number. | S12: =IF(NOT(ISBLANK(E12)), ROUND(((IF(E12="yes",1,0)*'Grading Scale'!E$2)+(IF(F12="yes",1,0)*'Grading Scale'!E$3)+(IF(G12="yes",1,0)*'Grading Scale'!E$4)+(IF(H12="yes",1,0)*'Grading Scale'!E$5)+(IF(I12="yes",1,0)*'Grading Scale'!E$6)+(IF(J12="yes",1,0)*'Grading Scale'!E$7)+(IF(K12="yes",1,0)*'Grading Scale'!E$8)+(IF(L12="yes",1,0)*'Grading Scale'!E$9)+(IF(M12="yes",1,0)*'Grading Scale'!E$10)+(IF(N12="yes",1,0)*'Grading Scale'!E$11)+(IF(O12="yes",1,0)*'Grading Scale'!E$12)+(IF(P12="yes",1,0)*'Grading Scale'!E$13))/'Grading Scale'!E$14*100,0), "") -> 85 | T12: =IF(ISNUMBER(S12),VLOOKUP(S12,'Grading Scale'!$A$2:$B$14, 2), "") -> B
A13: 42408 | B13: Alaska | C13: Companies | D13: =IF(NOT(ISBLANK(C13)), VLOOKUP(C13,'Dataset Descriptions'!$A$2:$B$10, 2, FALSE), "") -> The register of all corporations that exist in the state. | E13: yes | F13: yes | G13: yes | H13: yes | I13: yes | J13: yes | K13: yes | L13: no | M13: yes | N13: no | O13: yes | P13: yes | Q13: https://www.commerce.alaska.gov/cbp/Main/CBPLSearch.aspx?mode=Corp | R13: Data is available in links in the sidebar. | S13: =IF(NOT(ISBLANK(E13)), ROUND(((IF(E13="yes",1,0)*'Grading Scale'!E$2)+(IF(F13="yes",1,0)*'Grading Scale'!E$3)+(IF(G13="yes",1,0)*'Grading Scale'!E$4)+(IF(H13="yes",1,0)*'Grading Scale'!E$5)+(IF(I13="yes",1,0)*'Grading Scale'!E$6)+(IF(J13="yes",1,0)*'Grading Scale'!E$7)+(IF(K13="yes",1,0)*'Grading Scale'!E$8)+(IF(L13="yes",1,0)*'Grading Scale'!E$9)+(IF(M13="yes",1,0)*'Grading Scale'!E$10)+(IF(N13="yes",1,0)*'Grading Scale'!E$11)+(IF(O13="yes",1,0)*'Grading Scale'!E$12)+(IF(P13="yes",1,0)*'Grading Scale'!E$13))/'Grading Scale'!E$14*100,0), "") -> 90 | T13: =IF(ISNUMBER(S13),VLOOKUP(S13,'Grading Scale'!$A$2:$B$14, 2), "") -> A−
A14: 42408 | B14: Alaska | C14: Incarceration | D14: =IF(NOT(ISBLANK(C14)), VLOOKUP(C14,'Dataset Descriptions'!$A$2:$B$10, 2, FALSE), "") -> Per-facility inmate population records. | E14: yes | F14: yes | G14: yes | H14: yes | I14: yes | J14: no | K14: yes | L14: yes | M14: yes | N14: no | O14: no | P14: no | Q14: http://www.correct.state.ak.us/administrative-services/research-records | R14: Provided as a PDF, as a small part of a much larger annual report. Incomplete as it lacks historical figures and facility capacity data. Updated annually. | S14: =IF(NOT(ISBLANK(E14)), ROUND(((IF(E14="yes",1,0)*'Grading Scale'!E$2)+(IF(F14="yes",1,0)*'Grading Scale'!E$3)+(IF(G14="yes",1,0)*'Grading Scale'!E$4)+(IF(H14="yes",1,0)*'Grading Scale'!E$5)+(IF(I14="yes",1,0)*'Grading Scale'!E$6)+(IF(J14="yes",1,0)*'Grading Scale'!E$7)+(IF(K14="yes",1,0)*'Grading Scale'!E$8)+(IF(L14="yes",1,0)*'Grading Scale'!E$9)+(IF(M14="yes",1,0)*'Grading Scale'!E$10)+(IF(N14="yes",1,0)*'Grading Scale'!E$11)+(IF(O14="yes",1,0)*'Grading Scale'!E$12)+(IF(P14="yes",1,0)*'Grading Scale'!E$13))/'Grading Scale'!E$14*100,0), "") -> 45 | T14: =IF(ISNUMBER(S14),VLOOKUP(S14,'Grading Scale'!$A$2:$B$14, 2), "") -> F
A15: 42408 | B15: Alaska | C15: Legislation | D15: =IF(NOT(ISBLANK(C15)), VLOOKUP(C15,'Dataset Descriptions'!$A$2:$B$10, 2, FALSE), "") -> Bills before the legislature, and the legislators that comprise it. | E15: yes | F15: yes | G15: yes | H15: yes | I15: yes | J15: no | K15: no | L15: no | M15: yes | N15: no | O15: no | P15: no | Q15: http://www.legis.state.ak.us/ | R15: Incomplete, because it does not specify the date that legislators took office. | S15: =IF(NOT(ISBLANK(E15)), ROUND(((IF(E15="yes",1,0)*'Grading Scale'!E$2)+(IF(F15="yes",1,0)*'Grading Scale'!E$3)+(IF(G15="yes",1,0)*'Grading Scale'!E$4)+(IF(H15="yes",1,0)*'Grading Scale'!E$5)+(IF(I15="yes",1,0)*'Grading Scale'!E$6)+(IF(J15="yes",1,0)*'Grading Scale'!E$7)+(IF(K15="yes",1,0)*'Grading Scale'!E$8)+(IF(L15="yes",1,0)*'Grading Scale'!E$9)+(IF(M15="yes",1,0)*'Grading Scale'!E$10)+(IF(N15="yes",1,0)*'Grading Scale'!E$11)+(IF(O15="yes",1,0)*'Grading Scale'!E$12)+(IF(P15="yes",1,0)*'Grading Scale'!E$13))/'Grading Scale'!E$14*100,0), "") -> 35 | T15: =IF(ISNUMBER(S15),VLOOKUP(S15,'Grading Scale'!$A$2:$B$14, 2), "") -> F
A16: 42408 | B16: Alaska | C16: Population Projections | D16: =IF(NOT(ISBLANK(C16)), VLOOKUP(C16,'Dataset Descriptions'!$A$2:$B$10, 2, FALSE), "") -> Forecasts of municipal-level changes in population over coming years. | E16: yes | F16: yes | G16: yes | H16: yes | I16: yes | J16: yes | K16: yes | L16: no | M16: yes | N16: no | O16: no | P16: no | Q16: http://labor.alaska.gov/research/pop/popproj.htm | R16: Forecasts are broken down by boroughs and census areas, but no FIPS codes or GNIS IDs are provided for them, making the data incomplete. | S16: =IF(NOT(ISBLANK(E16)), ROUND(((IF(E16="yes",1,0)*'Grading Scale'!E$2)+(IF(F16="yes",1,0)*'Grading Scale'!E$3)+(IF(G16="yes",1,0)*'Grading Scale'!E$4)+(IF(H16="yes",1,0)*'Grading Scale'!E$5)+(IF(I16="yes",1,0)*'Grading Scale'!E$6)+(IF(J16="yes",1,0)*'Grading Scale'!E$7)+(IF(K16="yes",1,0)*'Grading Scale'!E$8)+(IF(L16="yes",1,0)*'Grading Scale'!E$9)+(IF(M16="yes",1,0)*'Grading Scale'!E$10)+(IF(N16="yes",1,0)*'Grading Scale'!E$11)+(IF(O16="yes",1,0)*'Grading Scale'!E$12)+(IF(P16="yes",1,0)*'Grading Scale'!E$13))/'Grading Scale'!E$14*100,0), "") -> 80 | T16: =IF(ISNUMBER(S16),VLOOKUP(S16,'Grading Scale'!$A$2:$B$14, 2), "") -> B−
A17: 42408 | B17: Alaska | C17: Real Estate | D17: =IF(NOT(ISBLANK(C17)), VLOOKUP(C17,'Dataset Descriptions'!$A$2:$B$10, 2, FALSE), "") -> State-owned land and buildings. | E17: unsure | F17: unsure | G17: unsure | H17: unsure | I17: no | J17: unsure | K17: unsure | L17: unsure | M17: unsure | N17: no | O17: unsure | P17: unsure | R17: No such records or references to them can be found, for either land or buildings. | S17: =IF(NOT(ISBLANK(E17)), ROUND(((IF(E17="yes",1,0)*'Grading Scale'!E$2)+(IF(F17="yes",1,0)*'Grading Scale'!E$3)+(IF(G17="yes",1,0)*'Grading Scale'!E$4)+(IF(H17="yes",1,0)*'Grading Scale'!E$5)+(IF(I17="yes",1,0)*'Grading Scale'!E$6)+(IF(J17="yes",1,0)*'Grading Scale'!E$7)+(IF(K17="yes",1,0)*'Grading Scale'!E$8)+(IF(L17="yes",1,0)*'Grading Scale'!E$9)+(IF(M17="yes",1,0)*'Grading Scale'!E$10)+(IF(N17="yes",1,0)*'Grading Scale'!E$11)+(IF(O17="yes",1,0)*'Grading Scale'!E$12)+(IF(P17="yes",1,0)*'Grading Scale'!E$13))/'Grading Scale'!E$14*100,0), "") -> 0 | T17: =IF(ISNUMBER(S17),VLOOKUP(S17,'Grading Scale'!$A$2:$B$14, 2), "") -> F
A18: 42408 | B18: Alaska | C18: Restaurant Inspections | D18: =IF(NOT(ISBLANK(C18)), VLOOKUP(C18,'Dataset Descriptions'!$A$2:$B$10, 2, FALSE), "") -> Health inspections of establishments that serve food to the public. | E18: yes | F18: yes | G18: yes | H18: yes | I18: yes | J18: no | K18: no | L18: yes | M18: yes | N18: no | O18: no | P18: yes | Q18: http://ak.healthinspections.us/alaska/ | R18: These are links to PDFs of reports. | S18: =IF(NOT(ISBLANK(E18)), ROUND(((IF(E18="yes",1,0)*'Grading Scale'!E$2)+(IF(F18="yes",1,0)*'Grading Scale'!E$3)+(IF(G18="yes",1,0)*'Grading Scale'!E$4)+(IF(H18="yes",1,0)*'Grading Scale'!E$5)+(IF(I18="yes",1,0)*'Grading Scale'!E$6)+(IF(J18="yes",1,0)*'Grading Scale'!E$7)+(IF(K18="yes",1,0)*'Grading Scale'!E$8)+(IF(L18="yes",1,0)*'Grading Scale'!E$9)+(IF(M18="yes",1,0)*'Grading Scale'!E$10)+(IF(N18="yes",1,0)*'Grading Scale'!E$11)+(IF(O18="yes",1,0)*'Grading Scale'!E$12)+(IF(P18="yes",1,0)*'Grading Scale'!E$13))/'Grading Scale'!E$14*100,0), "") -> 45 | T18: =IF(ISNUMBER(S18),VLOOKUP(S18,'Grading Scale'!$A$2:$B$14, 2), "") -> F
A19: 42408 | B19: Alaska | C19: Vehicle Crashes | D19: =IF(NOT(ISBLANK(C19)), VLOOKUP(C19,'Dataset Descriptions'!$A$2:$B$10, 2, FALSE), "") -> Incident-level reportable motor vehicle crash records. | E19: yes | F19: yes | G19: yes | H19: yes | I19: yes | J19: no | K19: yes | L19: yes | M19: no | N19: no | O19: no | P19: no | Q19: http://www.dot.alaska.gov/stwdplng/transdata/crash.shtml | R19: These are statistics, not data, and they haven't been updated in 5 years. Alaska has a proper data storage system for crash records, called "Highway Data Port," but the URL where it once lived now generates a 404, and we have been unable to track it down. | S19: =IF(NOT(ISBLANK(E19)), ROUND(((IF(E19="yes",1,0)*'Grading Scale'!E$2)+(IF(F19="yes",1,0)*'Grading Scale'!E$3)+(IF(G19="yes",1,0)*'Grading Scale'!E$4)+(IF(H19="yes",1,0)*'Grading Scale'!E$5)+(IF(I19="yes",1,0)*'Grading Scale'!E$6)+(IF(J19="yes",1,0)*'Grading Scale'!E$7)+(IF(K19="yes",1,0)*'Grading Scale'!E$8)+(IF(L19="yes",1,0)*'Grading Scale'!E$9)+(IF(M19="yes",1,0)*'Grading Scale'!E$10)+(IF(N19="yes",1,0)*'Grading Scale'!E$11)+(IF(O19="yes",1,0)*'Grading Scale'!E$12)+(IF(P19="yes",1,0)*'Grading Scale'!E$13))/'Grading Scale'!E$14*100,0), "") -> 40 | T19: =IF(ISNUMBER(S19),VLOOKUP(S19,'Grading Scale'!$A$2:$B$14, 2), "") -> F
A20: 42338 | B20: Arizona | C20: Address Points | D20: =IF(NOT(ISBLANK(C20)), VLOOKUP(C20,'Dataset Descriptions'!$A$2:$B$10, 2, FALSE), "") -> The geographic coordinates for physical addresses. | E20: no | F20: no | G20: no | H20: no | I20: no | J20: no | K20: no | L20: no | M20: no | N20: no | O20: no | P20: no | S20: =IF(NOT(ISBLANK(E20)), ROUND(((IF(E20="yes",1,0)*'Grading Scale'!E$2)+(IF(F20="yes",1,0)*'Grading Scale'!E$3)+(IF(G20="yes",1,0)*'Grading Scale'!E$4)+(IF(H20="yes",1,0)*'Grading Scale'!E$5)+(IF(I20="yes",1,0)*'Grading Scale'!E$6)+(IF(J20="yes",1,0)*'Grading Scale'!E$7)+(IF(K20="yes",1,0)*'Grading Scale'!E$8)+(IF(L20="yes",1,0)*'Grading Scale'!E$9)+(IF(M20="yes",1,0)*'Grading Scale'!E$10)+(IF(N20="yes",1,0)*'Grading Scale'!E$11)+(IF(O20="yes",1,0)*'Grading Scale'!E$12)+(IF(P20="yes",1,0)*'Grading Scale'!E$13))/'Grading Scale'!E$14*100,0), "") -> 0 | T20: =IF(ISNUMBER(S20),VLOOKUP(S20,'Grading Scale'!$A$2:$B$14, 2), "") -> F
A21: 42374 | B21: Arizona | C21: Checkbook | D21: =IF(NOT(ISBLANK(C21)), VLOOKUP(C21,'Dataset Descriptions'!$A$2:$B$10, 2, FALSE), "") -> Transaction-level, per-agency spending records. | E21: yes | F21: yes | G21: yes | H21: yes | I21: yes | J21: yes | K21: yes | L21: yes | M21: no | N21: no | O21: no | P21: yes | Q21: http://www.azcheckbook.com/ | R21: Data provided as a zipped TSV. It is only updated once annually, in September. | S21: =IF(NOT(ISBLANK(E21)), ROUND(((IF(E21="yes",1,0)*'Grading Scale'!E$2)+(IF(F21="yes",1,0)*'Grading Scale'!E$3)+(IF(G21="yes",1,0)*'Grading Scale'!E$4)+(IF(H21="yes",1,0)*'Grading Scale'!E$5)+(IF(I21="yes",1,0)*'Grading Scale'!E$6)+(IF(J21="yes",1,0)*'Grading Scale'!E$7)+(IF(K21="yes",1,0)*'Grading Scale'!E$8)+(IF(L21="yes",1,0)*'Grading Scale'!E$9)+(IF(M21="yes",1,0)*'Grading Scale'!E$10)+(IF(N21="yes",1,0)*'Grading Scale'!E$11)+(IF(O21="yes",1,0)*'Grading Scale'!E$12)+(IF(P21="yes",1,0)*'Grading Scale'!E$13))/'Grading Scale'!E$14*100,0), "") -> 85 | T21: =IF(ISNUMBER(S21),VLOOKUP(S21,'Grading Scale'!$A$2:$B$14, 2), "") -> B
A22: 42402 | B22: Arizona | C22: Companies | D22: =IF(NOT(ISBLANK(C22)), VLOOKUP(C22,'Dataset Descriptions'!$A$2:$B$10, 2, FALSE), "") -> The register of all corporations that exist in the state. | E22: yes | F22: yes | G22: yes | H22: no | I22: yes | J22: yes | K22: yes | L22: yes | M22: yes | N22: no | O22: no | P22: yes | Q22: http://ecorp.azcc.gov/ | R22: HTML version is free. Actual data costs $1,000. | S22: =IF(NOT(ISBLANK(E22)), ROUND(((IF(E22="yes",1,0)*'Grading Scale'!E$2)+(IF(F22="yes",1,0)*'Grading Scale'!E$3)+(IF(G22="yes",1,0)*'Grading Scale'!E$4)+(IF(H22="yes",1,0)*'Grading Scale'!E$5)+(IF(I22="yes",1,0)*'Grading Scale'!E$6)+(IF(J22="yes",1,0)*'Grading Scale'!E$7)+(IF(K22="yes",1,0)*'Grading Scale'!E$8)+(IF(L22="yes",1,0)*'Grading Scale'!E$9)+(IF(M22="yes",1,0)*'Grading Scale'!E$10)+(IF(N22="yes",1,0)*'Grading Scale'!E$11)+(IF(O22="yes",1,0)*'Grading Scale'!E$12)+(IF(P22="yes",1,0)*'Grading Scale'!E$13))/'Grading Scale'!E$14*100,0), "") -> 75 | T22: =IF(ISNUMBER(S22),VLOOKUP(S22,'Grading Scale'!$A$2:$B$14, 2), "") -> C
A23: 42402 | B23: Arizona | C23: Incarceration | D23: =IF(NOT(ISBLANK(C23)), VLOOKUP(C23,'Dataset Descriptions'!$A$2:$B$10, 2, FALSE), "") -> Per-facility inmate population records. | E23: yes | F23: yes | G23: yes | H23: yes | I23: yes | J23: no | K23: no | L23: no | M23: yes | O23: yes | P23: no | Q23: https://corrections.az.gov/node/452 | R23: Provided as PDFs, generated by Excel. Updated daily. Site uses SSL. | S23: =IF(NOT(ISBLANK(E23)), ROUND(((IF(E23="yes",1,0)*'Grading Scale'!E$2)+(IF(F23="yes",1,0)*'Grading Scale'!E$3)+(IF(G23="yes",1,0)*'Grading Scale'!E$4)+(IF(H23="yes",1,0)*'Grading Scale'!E$5)+(IF(I23="yes",1,0)*'Grading Scale'!E$6)+(IF(J23="yes",1,0)*'Grading Scale'!E$7)+(IF(K23="yes",1,0)*'Grading Scale'!E$8)+(IF(L23="yes",1,0)*'Grading Scale'!E$9)+(IF(M23="yes",1,0)*'Grading Scale'!E$10)+(IF(N23="yes",1,0)*'Grading Scale'!E$11)+(IF(O23="yes",1,0)*'Grading Scale'!E$12)+(IF(P23="yes",1,0)*'Grading Scale'!E$13))/'Grading Scale'!E$14*100,0), "") -> 40 | T23: =IF(ISNUMBER(S23),VLOOKUP(S23,'Grading Scale'!$A$2:$B$14, 2), "") -> F
A24: 42338 | B24: Arizona | C24: Legislation | D24: =IF(NOT(ISBLANK(C24)), VLOOKUP(C24,'Dataset Descriptions'!$A$2:$B$10, 2, FALSE), "") -> Bills before the legislature, and the legislators that comprise it. | E24: yes | F24: yes | G24: yes | H24: yes | I24: yes | J24: no | K24: no | L24: no | M24: yes | N24: no | O24: no | P24: yes | Q24: http://www.azleg.gov/ | S24: =IF(NOT(ISBLANK(E24)), ROUND(((IF(E24="yes",1,0)*'Grading Scale'!E$2)+(IF(F24="yes",1,0)*'Grading Scale'!E$3)+(IF(G24="yes",1,0)*'Grading Scale'!E$4)+(IF(H24="yes",1,0)*'Grading Scale'!E$5)+(IF(I24="yes",1,0)*'Grading Scale'!E$6)+(IF(J24="yes",1,0)*'Grading Scale'!E$7)+(IF(K24="yes",1,0)*'Grading Scale'!E$8)+(IF(L24="yes",1,0)*'Grading Scale'!E$9)+(IF(M24="yes",1,0)*'Grading Scale'!E$10)+(IF(N24="yes",1,0)*'Grading Scale'!E$11)+(IF(O24="yes",1,0)*'Grading Scale'!E$12)+(IF(P24="yes",1,0)*'Grading Scale'!E$13))/'Grading Scale'!E$14*100,0), "") -> 40 | T24: =IF(ISNUMBER(S24),VLOOKUP(S24,'Grading Scale'!$A$2:$B$14, 2), "") -> F
A25: 42402 | B25: Arizona | C25: Population Projections | D25: =IF(NOT(ISBLANK(C25)), VLOOKUP(C25,'Dataset Descriptions'!$A$2:$B$10, 2, FALSE), "") -> Forecasts of municipal-level changes in population over coming years. | E25: yes | F25: yes | G25: yes | H25: yes | I25: yes | J25: yes | K25: yes | L25: yes | M25: yes | N25: no | O25: no | P25: no | Q25: https://population.az.gov/ | R25: No GNIS IDs. | S25: =IF(NOT(ISBLANK(E25)), ROUND(((IF(E25="yes",1,0)*'Grading Scale'!E$2)+(IF(F25="yes",1,0)*'Grading Scale'!E$3)+(IF(G25="yes",1,0)*'Grading Scale'!E$4)+(IF(H25="yes",1,0)*'Grading Scale'!E$5)+(IF(I25="yes",1,0)*'Grading Scale'!E$6)+(IF(J25="yes",1,0)*'Grading Scale'!E$7)+(IF(K25="yes",1,0)*'Grading Scale'!E$8)+(IF(L25="yes",1,0)*'Grading Scale'!E$9)+(IF(M25="yes",1,0)*'Grading Scale'!E$10)+(IF(N25="yes",1,0)*'Grading Scale'!E$11)+(IF(O25="yes",1,0)*'Grading Scale'!E$12)+(IF(P25="yes",1,0)*'Grading Scale'!E$13))/'Grading Scale'!E$14*100,0), "") -> 85 | T25: =IF(ISNUMBER(S25),VLOOKUP(S25,'Grading Scale'!$A$2:$B$14, 2), "") -> B
A26: 42360 | B26: Arizona | C26: Real Estate | D26: =IF(NOT(ISBLANK(C26)), VLOOKUP(C26,'Dataset Descriptions'!$A$2:$B$10, 2, FALSE), "") -> State-owned land and buildings. | E26: no | F26: no | G26: no | H26: no | I26: no | J26: no | K26: no | L26: no | M26: no | N26: no | O26: no | P26: no | S26: =IF(NOT(ISBLANK(E26)), ROUND(((IF(E26="yes",1,0)*'Grading Scale'!E$2)+(IF(F26="yes",1,0)*'Grading Scale'!E$3)+(IF(G26="yes",1,0)*'Grading Scale'!E$4)+(IF(H26="yes",1,0)*'Grading Scale'!E$5)+(IF(I26="yes",1,0)*'Grading Scale'!E$6)+(IF(J26="yes",1,0)*'Grading Scale'!E$7)+(IF(K26="yes",1,0)*'Grading Scale'!E$8)+(IF(L26="yes",1,0)*'Grading Scale'!E$9)+(IF(M26="yes",1,0)*'Grading Scale'!E$10)+(IF(N26="yes",1,0)*'Grading Scale'!E$11)+(IF(O26="yes",1,0)*'Grading Scale'!E$12)+(IF(P26="yes",1,0)*'Grading Scale'!E$13))/'Grading Scale'!E$14*100,0), "") -> 0 | T26: =IF(ISNUMBER(S26),VLOOKUP(S26,'Grading Scale'!$A$2:$B$14, 2), "") -> F
A27: 42338 | B27: Arizona | C27: Restaurant Inspections | D27: =IF(NOT(ISBLANK(C27)), VLOOKUP(C27,'Dataset Descriptions'!$A$2:$B$10, 2, FALSE), "") -> Health inspections of establishments that serve food to the public. | E27: no | F27: no | G27: no | H27: no | I27: no | J27: no | K27: no | L27: no | M27: no | N27: no | O27: no | P27: no | S27: =IF(NOT(ISBLANK(E27)), ROUND(((IF(E27="yes",1,0)*'Grading Scale'!E$2)+(IF(F27="yes",1,0)*'Grading Scale'!E$3)+(IF(G27="yes",1,0)*'Grading Scale'!E$4)+(IF(H27="yes",1,0)*'Grading Scale'!E$5)+(IF(I27="yes",1,0)*'Grading Scale'!E$6)+(IF(J27="yes",1,0)*'Grading Scale'!E$7)+(IF(K27="yes",1,0)*'Grading Scale'!E$8)+(IF(L27="yes",1,0)*'Grading Scale'!E$9)+(IF(M27="yes",1,0)*'Grading Scale'!E$10)+(IF(N27="yes",1,0)*'Grading Scale'!E$11)+(IF(O27="yes",1,0)*'Grading Scale'!E$12)+(IF(P27="yes",1,0)*'Grading Scale'!E$13))/'Grading Scale'!E$14*100,0), "") -> 0 | T27: =IF(ISNUMBER(S27),VLOOKUP(S27,'Grading Scale'!$A$2:$B$14, 2), "") -> F
A28: 42375 | B28: Arizona | C28: Vehicle Crashes | D28: =IF(NOT(ISBLANK(C28)), VLOOKUP(C28,'Dataset Descriptions'!$A$2:$B$10, 2, FALSE), "") -> Incident-level reportable motor vehicle crash records. | E28: yes | F28: yes | G28: yes | H28: yes | I28: yes | J28: no | K28: no | L28: no | M28: yes | N28: no | O28: no | P28: no | Q28: http://azdot.gov/mvd/Statistics/arizona-motor-vehicle-crash-facts | R28: These are statistics, not data. | S28: =IF(NOT(ISBLANK(E28)), ROUND(((IF(E28="yes",1,0)*'Grading Scale'!E$2)+(IF(F28="yes",1,0)*'Grading Scale'!E$3)+(IF(G28="yes",1,0)*'Grading Scale'!E$4)+(IF(H28="yes",1,0)*'Grading Scale'!E$5)+(IF(I28="yes",1,0)*'Grading Scale'!E$6)+(IF(J28="yes",1,0)*'Grading Scale'!E$7)+(IF(K28="yes",1,0)*'Grading Scale'!E$8)+(IF(L28="yes",1,0)*'Grading Scale'!E$9)+(IF(M28="yes",1,0)*'Grading Scale'!E$10)+(IF(N28="yes",1,0)*'Grading Scale'!E$11)+(IF(O28="yes",1,0)*'Grading Scale'!E$12)+(IF(P28="yes",1,0)*'Grading Scale'!E$13))/'Grading Scale'!E$14*100,0), "") -> 35 | T28: =IF(ISNUMBER(S28),VLOOKUP(S28,'Grading Scale'!$A$2:$B$14, 2), "") -> F
A29: 42388 | B29: Arkansas | C29: Address Points | D29: =IF(NOT(ISBLANK(C29)), VLOOKUP(C29,'Dataset Descriptions'!$A$2:$B$10, 2, FALSE), "") -> The geographic coordinates for physical addresses. | E29: yes | F29: yes | G29: yes | H29: yes | I29: yes | J29: yes | K29: yes | L29: yes | M29: yes | N29: no | O29: no | P29: yes | Q29: http://gis.arkansas.gov/?product=situs-address-points | R29: Data is affirmatively placed in the public domain. | S29: =IF(NOT(ISBLANK(E29)), ROUND(((IF(E29="yes",1,0)*'Grading Scale'!E$2)+(IF(F29="yes",1,0)*'Grading Scale'!E$3)+(IF(G29="yes",1,0)*'Grading Scale'!E$4)+(IF(H29="yes",1,0)*'Grading Scale'!E$5)+(IF(I29="yes",1,0)*'Grading Scale'!E$6)+(IF(J29="yes",1,0)*'Grading Scale'!E$7)+(IF(K29="yes",1,0)*'Grading Scale'!E$8)+(IF(L29="yes",1,0)*'Grading Scale'!E$9)+(IF(M29="yes",1,0)*'Grading Scale'!E$10)+(IF(N29="yes",1,0)*'Grading Scale'!E$11)+(IF(O29="yes",1,0)*'Grading Scale'!E$12)+(IF(P29="yes",1,0)*'Grading Scale'!E$13))/'Grading Scale'!E$14*100,0), "") -> 90 | T29: =IF(ISNUMBER(S29),VLOOKUP(S29,'Grading Scale'!$A$2:$B$14, 2), "") -> A−
A30: 42388 | B30: Arkansas | C30: Checkbook | D30: =IF(NOT(ISBLANK(C30)), VLOOKUP(C30,'Dataset Descriptions'!$A$2:$B$10, 2, FALSE), "") -> Transaction-level, per-agency spending records. | E30: yes | F30: yes | G30: yes | H30: yes | I30: yes | J30: yes | K30: no | L30: no | M30: yes | N30: no | O30: yes | P30: no | Q30: https://www.ark.org/dfa/transparency/expenditures.php | R30: Data lacks a description of the purpose of the transaction, as well as a voucher or check number. Provided as CSV and Excel files. | S30: =IF(NOT(ISBLANK(E30)), ROUND(((IF(E30="yes",1,0)*'Grading Scale'!E$2)+(IF(F30="yes",1,0)*'Grading Scale'!E$3)+(IF(G30="yes",1,0)*'Grading Scale'!E$4)+(IF(H30="yes",1,0)*'Grading Scale'!E$5)+(IF(I30="yes",1,0)*'Grading Scale'!E$6)+(IF(J30="yes",1,0)*'Grading Scale'!E$7)+(IF(K30="yes",1,0)*'Grading Scale'!E$8)+(IF(L30="yes",1,0)*'Grading Scale'!E$9)+(IF(M30="yes",1,0)*'Grading Scale'!E$10)+(IF(N30="yes",1,0)*'Grading Scale'!E$11)+(IF(O30="yes",1,0)*'Grading Scale'!E$12)+(IF(P30="yes",1,0)*'Grading Scale'!E$13))/'Grading Scale'!E$14*100,0), "") -> 80 | T30: =IF(ISNUMBER(S30),VLOOKUP(S30,'Grading Scale'!$A$2:$B$14, 2), "") -> B−
A31: 42384 | B31: Arkansas | C31: Companies | D31: =IF(NOT(ISBLANK(C31)), VLOOKUP(C31,'Dataset Descriptions'!$A$2:$B$10, 2, FALSE), "") -> The register of all corporations that exist in the state. | E31: yes | F31: yes | G31: yes | H31: no | I31: yes | J31: yes | K31: yes | L31: no | M31: yes | N31: no | O31: unsure | P31: unsure | Q31: https://www.ark.org/sos/special/index.php | R31: Requires a $95/year account with the Information Network of Arkansas. Data then costs $2,000 / month. This made it impossible to perform a complete evaluation of this dataset. | S31: =IF(NOT(ISBLANK(E31)), ROUND(((IF(E31="yes",1,0)*'Grading Scale'!E$2)+(IF(F31="yes",1,0)*'Grading Scale'!E$3)+(IF(G31="yes",1,0)*'Grading Scale'!E$4)+(IF(H31="yes",1,0)*'Grading Scale'!E$5)+(IF(I31="yes",1,0)*'Grading Scale'!E$6)+(IF(J31="yes",1,0)*'Grading Scale'!E$7)+(IF(K31="yes",1,0)*'Grading Scale'!E$8)+(IF(L31="yes",1,0)*'Grading Scale'!E$9)+(IF(M31="yes",1,0)*'Grading Scale'!E$10)+(IF(N31="yes",1,0)*'Grading Scale'!E$11)+(IF(O31="yes",1,0)*'Grading Scale'!E$12)+(IF(P31="yes",1,0)*'Grading Scale'!E$13))/'Grading Scale'!E$14*100,0), "") -> 65 | T31: =IF(ISNUMBER(S31),VLOOKUP(S31,'Grading Scale'!$A$2:$B$14, 2), "") -> D
A32: 42388 | B32: Arkansas | C32: Incarceration | D32: =IF(NOT(ISBLANK(C32)), VLOOKUP(C32,'Dataset Descriptions'!$A$2:$B$10, 2, FALSE), "") -> Per-facility inmate population records. | E32: no | F32: no | G32: no | H32: no | I32: no | J32: no | K32: no | L32: no | M32: no | N32: no | O32: no | P32: no | R32: If this data exists, it appears that it would be at (http://adc.arkansas.gov/resources/Pages/Reports.aspx). This has various types of data, all as PDFs, but none of it correct for this. Note that they sell bulk data of inmate data (http://adc.arkansas.gov/onlineServices/Pages/dataDownload.aspx), requiring a $95/year account plus 10¢ per record, or $1,903.70 in total. This might make it possible to infer population data. | S32: =IF(NOT(ISBLANK(E32)), ROUND(((IF(E32="yes",1,0)*'Grading Scale'!E$2)+(IF(F32="yes",1,0)*'Grading Scale'!E$3)+(IF(G32="yes",1,0)*'Grading Scale'!E$4)+(IF(H32="yes",1,0)*'Grading Scale'!E$5)+(IF(I32="yes",1,0)*'Grading Scale'!E$6)+(IF(J32="yes",1,0)*'Grading Scale'!E$7)+(IF(K32="yes",1,0)*'Grading Scale'!E$8)+(IF(L32="yes",1,0)*'Grading Scale'!E$9)+(IF(M32="yes",1,0)*'Grading Scale'!E$10)+(IF(N32="yes",1,0)*'Grading Scale'!E$11)+(IF(O32="yes",1,0)*'Grading Scale'!E$12)+(IF(P32="yes",1,0)*'Grading Scale'!E$13))/'Grading Scale'!E$14*100,0), "") -> 0 | T32: =IF(ISNUMBER(S32),VLOOKUP(S32,'Grading Scale'!$A$2:$B$14, 2), "") -> F
A33: 42388 | B33: Arkansas | C33: Legislation | D33: =IF(NOT(ISBLANK(C33)), VLOOKUP(C33,'Dataset Descriptions'!$A$2:$B$10, 2, FALSE), "") -> Bills before the legislature, and the legislators that comprise it. | E33: yes | F33: yes | G33: yes | H33: yes | I33: yes | J33: no | K33: no | L33: yes | M33: yes | N33: no | O33: no | P33: yes | Q33: http://www.arkleg.state.ar.us/ | R33: There are third-party references to Arkansas providing CSV files of some legislative data, but our survey was not able to locate any such data. | S33: =IF(NOT(ISBLANK(E33)), ROUND(((IF(E33="yes",1,0)*'Grading Scale'!E$2)+(IF(F33="yes",1,0)*'Grading Scale'!E$3)+(IF(G33="yes",1,0)*'Grading Scale'!E$4)+(IF(H33="yes",1,0)*'Grading Scale'!E$5)+(IF(I33="yes",1,0)*'Grading Scale'!E$6)+(IF(J33="yes",1,0)*'Grading Scale'!E$7)+(IF(K33="yes",1,0)*'Grading Scale'!E$8)+(IF(L33="yes",1,0)*'Grading Scale'!E$9)+(IF(M33="yes",1,0)*'Grading Scale'!E$10)+(IF(N33="yes",1,0)*'Grading Scale'!E$11)+(IF(O33="yes",1,0)*'Grading Scale'!E$12)+(IF(P33="yes",1,0)*'Grading Scale'!E$13))/'Grading Scale'!E$14*100,0), "") -> 45 | T33: =IF(ISNUMBER(S33),VLOOKUP(S33,'Grading Scale'!$A$2:$B$14, 2), "") -> F
A34: 42395 | B34: Arkansas | C34: Population Projections | D34: =IF(NOT(ISBLANK(C34)), VLOOKUP(C34,'Dataset Descriptions'!$A$2:$B$10, 2, FALSE), "") -> Forecasts of municipal-level changes in population over coming years. | E34: yes | F34: yes | G34: yes | H34: yes | I34: yes | J34: yes | K34: yes | L34: no | M34: yes | N34: no | O34: no | P34: no | Q34: http://iea.ualr.edu/population-estimates-a-projections.html#proj | R34: Provided as an Excel file. Lacks FIPS codes or GNIS IDs identifying localities. | S34: =IF(NOT(ISBLANK(E34)), ROUND(((IF(E34="yes",1,0)*'Grading Scale'!E$2)+(IF(F34="yes",1,0)*'Grading Scale'!E$3)+(IF(G34="yes",1,0)*'Grading Scale'!E$4)+(IF(H34="yes",1,0)*'Grading Scale'!E$5)+(IF(I34="yes",1,0)*'Grading Scale'!E$6)+(IF(J34="yes",1,0)*'Grading Scale'!E$7)+(IF(K34="yes",1,0)*'Grading Scale'!E$8)+(IF(L34="yes",1,0)*'Grading Scale'!E$9)+(IF(M34="yes",1,0)*'Grading Scale'!E$10)+(IF(N34="yes",1,0)*'Grading Scale'!E$11)+(IF(O34="yes",1,0)*'Grading Scale'!E$12)+(IF(P34="yes",1,0)*'Grading Scale'!E$13))/'Grading Scale'!E$14*100,0), "") -> 80 | T34: =IF(ISNUMBER(S34),VLOOKUP(S34,'Grading Scale'!$A$2:$B$14, 2), "") -> B−
A35: 42388 | B35: Arkansas | C35: Real Estate | D35: =IF(NOT(ISBLANK(C35)), VLOOKUP(C35,'Dataset Descriptions'!$A$2:$B$10, 2, FALSE), "") -> State-owned land and buildings. | E35: unsure | F35: unsure | G35: unsure | H35: unsure | I35: no | J35: unsure | K35: unsure | L35: unsure | M35: unsure | N35: no | O35: unsure | P35: unsure | S35: =IF(NOT(ISBLANK(E35)), ROUND(((IF(E35="yes",1,0)*'Grading Scale'!E$2)+(IF(F35="yes",1,0)*'Grading Scale'!E$3)+(IF(G35="yes",1,0)*'Grading Scale'!E$4)+(IF(H35="yes",1,0)*'Grading Scale'!E$5)+(IF(I35="yes",1,0)*'Grading Scale'!E$6)+(IF(J35="yes",1,0)*'Grading Scale'!E$7)+(IF(K35="yes",1,0)*'Grading Scale'!E$8)+(IF(L35="yes",1,0)*'Grading Scale'!E$9)+(IF(M35="yes",1,0)*'Grading Scale'!E$10)+(IF(N35="yes",1,0)*'Grading Scale'!E$11)+(IF(O35="yes",1,0)*'Grading Scale'!E$12)+(IF(P35="yes",1,0)*'Grading Scale'!E$13))/'Grading Scale'!E$14*100,0), "") -> 0 | T35: =IF(ISNUMBER(S35),VLOOKUP(S35,'Grading Scale'!$A$2:$B$14, 2), "") -> F
A36: 42388 | B36: Arkansas | C36: Restaurant Inspections | D36: =IF(NOT(ISBLANK(C36)), VLOOKUP(C36,'Dataset Descriptions'!$A$2:$B$10, 2, FALSE), "") -> Health inspections of establishments that serve food to the public. | E36: no | F36: no | G36: no | H36: no | I36: no | J36: no | K36: no | L36: no | M36: no | N36: no | O36: no | P36: no | R36: Arkansas does not provide this data on a statewide basis, state media reports indicate. | S36: =IF(NOT(ISBLANK(E36)), ROUND(((IF(E36="yes",1,0)*'Grading Scale'!E$2)+(IF(F36="yes",1,0)*'Grading Scale'!E$3)+(IF(G36="yes",1,0)*'Grading Scale'!E$4)+(IF(H36="yes",1,0)*'Grading Scale'!E$5)+(IF(I36="yes",1,0)*'Grading Scale'!E$6)+(IF(J36="yes",1,0)*'Grading Scale'!E$7)+(IF(K36="yes",1,0)*'Grading Scale'!E$8)+(IF(L36="yes",1,0)*'Grading Scale'!E$9)+(IF(M36="yes",1,0)*'Grading Scale'!E$10)+(IF(N36="yes",1,0)*'Grading Scale'!E$11)+(IF(O36="yes",1,0)*'Grading Scale'!E$12)+(IF(P36="yes",1,0)*'Grading Scale'!E$13))/'Grading Scale'!E$14*100,0), "") -> 0 | T36: =IF(ISNUMBER(S36),VLOOKUP(S36,'Grading Scale'!$A$2:$B$14, 2), "") -> F
A37: 42389 | B37: Arkansas | C37: Vehicle Crashes | D37: =IF(NOT(ISBLANK(C37)), VLOOKUP(C37,'Dataset Descriptions'!$A$2:$B$10, 2, FALSE), "") -> Incident-level reportable motor vehicle crash records. | E37: yes | F37: yes | G37: unsure | H37: unsure | I37: no | J37: yes | K37: unsure | L37: unsure | M37: unsure | N37: no | O37: unsure | P37: yes | Q37: http://asp.ark.org/services-and-programs/detail/highway-safety-office | R37: Arkansas participates in NHTSA's State Data System, so they can be known to be producing crash data meeting minimum standards. However, they do not share that data publicly. Instead, they provide only PDFs of overall statistics that, as of this writing, have not been updated in 2 years. | S37: =IF(NOT(ISBLANK(E37)), ROUND(((IF(E37="yes",1,0)*'Grading Scale'!E$2)+(IF(F37="yes",1,0)*'Grading Scale'!E$3)+(IF(G37="yes",1,0)*'Grading Scale'!E$4)+(IF(H37="yes",1,0)*'Grading Scale'!E$5)+(IF(I37="yes",1,0)*'Grading Scale'!E$6)+(IF(J37="yes",1,0)*'Grading Scale'!E$7)+(IF(K37="yes",1,0)*'Grading Scale'!E$8)+(IF(L37="yes",1,0)*'Grading Scale'!E$9)+(IF(M37="yes",1,0)*'Grading Scale'!E$10)+(IF(N37="yes",1,0)*'Grading Scale'!E$11)+(IF(O37="yes",1,0)*'Grading Scale'!E$12)+(IF(P37="yes",1,0)*'Grading Scale'!E$13))/'Grading Scale'!E$14*100,0), "") -> 50 | T37: =IF(ISNUMBER(S37),VLOOKUP(S37,'Grading Scale'!$A$2:$B$14, 2), "") -> F
A38: 42349 | B38: California | C38: Address Points | D38: =IF(NOT(ISBLANK(C38)), VLOOKUP(C38,'Dataset Descriptions'!$A$2:$B$10, 2, FALSE), "") -> The geographic coordinates for physical addresses. | E38: no | F38: no | G38: no | H38: no | I38: no | J38: no | K38: no | L38: no | M38: no | N38: no | O38: no | P38: no | S38: =IF(NOT(ISBLANK(E38)), ROUND(((IF(E38="yes",1,0)*'Grading Scale'!E$2)+(IF(F38="yes",1,0)*'Grading Scale'!E$3)+(IF(G38="yes",1,0)*'Grading Scale'!E$4)+(IF(H38="yes",1,0)*'Grading Scale'!E$5)+(IF(I38="yes",1,0)*'Grading Scale'!E$6)+(IF(J38="yes",1,0)*'Grading Scale'!E$7)+(IF(K38="yes",1,0)*'Grading Scale'!E$8)+(IF(L38="yes",1,0)*'Grading Scale'!E$9)+(IF(M38="yes",1,0)*'Grading Scale'!E$10)+(IF(N38="yes",1,0)*'Grading Scale'!E$11)+(IF(O38="yes",1,0)*'Grading Scale'!E$12)+(IF(P38="yes",1,0)*'Grading Scale'!E$13))/'Grading Scale'!E$14*100,0), "") -> 0 | T38: =IF(ISNUMBER(S38),VLOOKUP(S38,'Grading Scale'!$A$2:$B$14, 2), "") -> F
A39: 42402 | B39: California | C39: Checkbook | D39: =IF(NOT(ISBLANK(C39)), VLOOKUP(C39,'Dataset Descriptions'!$A$2:$B$10, 2, FALSE), "") -> Transaction-level, per-agency spending records. | E39: no | F39: no | G39: no | H39: no | I39: no | J39: no | K39: no | L39: no | M39: no | N39: no | O39: no | P39: no | S39: =IF(NOT(ISBLANK(E39)), ROUND(((IF(E39="yes",1,0)*'Grading Scale'!E$2)+(IF(F39="yes",1,0)*'Grading Scale'!E$3)+(IF(G39="yes",1,0)*'Grading Scale'!E$4)+(IF(H39="yes",1,0)*'Grading Scale'!E$5)+(IF(I39="yes",1,0)*'Grading Scale'!E$6)+(IF(J39="yes",1,0)*'Grading Scale'!E$7)+(IF(K39="yes",1,0)*'Grading Scale'!E$8)+(IF(L39="yes",1,0)*'Grading Scale'!E$9)+(IF(M39="yes",1,0)*'Grading Scale'!E$10)+(IF(N39="yes",1,0)*'Grading Scale'!E$11)+(IF(O39="yes",1,0)*'Grading Scale'!E$12)+(IF(P39="yes",1,0)*'Grading Scale'!E$13))/'Grading Scale'!E$14*100,0), "") -> 0 | T39: =IF(ISNUMBER(S39),VLOOKUP(S39,'Grading Scale'!$A$2:$B$14, 2), "") -> F
A40: 42338 | B40: California | C40: Companies | D40: =IF(NOT(ISBLANK(C40)), VLOOKUP(C40,'Dataset Descriptions'!$A$2:$B$10, 2, FALSE), "") -> The register of all corporations that exist in the state. | E40: yes | F40: yes | G40: yes | H40: yes | I40: yes | J40: no | K40: no | L40: no | M40: yes | N40: yes | O40: no | P40: no | Q40: http://kepler.sos.ca.gov/ | R40: Doesn’t list shares or officers. | S40: =IF(NOT(ISBLANK(E40)), ROUND(((IF(E40="yes",1,0)*'Grading Scale'!E$2)+(IF(F40="yes",1,0)*'Grading Scale'!E$3)+(IF(G40="yes",1,0)*'Grading Scale'!E$4)+(IF(H40="yes",1,0)*'Grading Scale'!E$5)+(IF(I40="yes",1,0)*'Grading Scale'!E$6)+(IF(J40="yes",1,0)*'Grading Scale'!E$7)+(IF(K40="yes",1,0)*'Grading Scale'!E$8)+(IF(L40="yes",1,0)*'Grading Scale'!E$9)+(IF(M40="yes",1,0)*'Grading Scale'!E$10)+(IF(N40="yes",1,0)*'Grading Scale'!E$11)+(IF(O40="yes",1,0)*'Grading Scale'!E$12)+(IF(P40="yes",1,0)*'Grading Scale'!E$13))/'Grading Scale'!E$14*100,0), "") -> 40 | T40: =IF(ISNUMBER(S40),VLOOKUP(S40,'Grading Scale'!$A$2:$B$14, 2), "") -> F
...

Sheet Grading Scale
A1: Low Score | B1: Grade | D1: Criterion | E1: Points
A2: 0 | B2: F | D2: Exists | E2: 0
A3: =E14*0.6 -> 60 | B3: D− | D3: Digitized | E3: 5
A4: =E14*0.63 -> 63 | B4: D | D4: Public | E4: 5
A5: =E14*0.67 -> 67 | B5: D+ | D5: Free | E5: 15
A6: =E14*0.7 -> 70 | B6: C− | D6: Online | E6: 5
A7: =E14*0.73 -> 73 | B7: C | D7: Machine readable | E7: 40
A8: =E14*0.77 -> 77 | B8: C+ | D8: Available in bulk | E8: 5
A9: =E14*0.8 -> 80 | B9: B− | D9: No restrictions | E9: 5
A10: =E14*0.83 -> 83 | B10: B | D10: Up-to-date | E10: 5
A11: =E14*0.87 -> 87 | B11: B+ | D11: In the state repository | E11: 5
A12: =E14*0.9 -> 90 | B12: A− | D12: Verifiable | E12: 5
A13: =E14*0.93 -> 93 | B13: A | D13: Complete | E13: 5
A14: =E14*0.97 -> 97 | B14: A+ | E14: =SUM(E2:E13) -> 100

Sheet Dataset Descriptions
A1: Type | B1: Description
A2: Companies | B2: The register of all corporations that exist in the state.
A3: Incarceration | B3: Per-facility inmate population records.
A4: Real Estate | B4: State-owned land and buildings.
A5: Checkbook | B5: Transaction-level, per-agency spending records.
A6: Address Points | B6: The geographic coordinates for physical addresses.
A7: Legislation | B7: Bills before the legislature, and the legislators that comprise it.
A8: Restaurant Inspections | B8: Health inspections of establishments that serve food to the public.
A9: Population Projections | B9: Forecasts of municipal-level changes in population over coming years.
A10: Vehicle Crashes | B10: Incident-level reportable motor vehicle crash records.

Sheet Places
A1: Name | B1: Score | C1: Grade | D1: Repository URL | E1: Comments
A2: {=INDEX('Census Data'!$B$2:$B$504, MATCH(0, COUNTIF($A$1:A1, 'Census Data'!$B$2:$B$504), 0))} -> Alabama | B2: =ROUND(AVERAGEIF('Census Data'!B$1:B$1004,A2,'Census Data'!S$1:S$1004),0) -> 37 | C2: =VLOOKUP(B2,'Grading Scale'!$A$2:$B$14, 2) -> F
A3: {=INDEX('Census Data'!$B$2:$B$504, MATCH(0, COUNTIF($A$1:A2, 'Census Data'!$B$2:$B$504), 0))} -> Alaska | B3: =ROUND(AVERAGEIF('Census Data'!B$1:B$1004,A3,'Census Data'!S$1:S$1004),0) -> 47 | C3: =VLOOKUP(B3,'Grading Scale'!$A$2:$B$14, 2) -> F
A4: {=INDEX('Census Data'!$B$2:$B$504, MATCH(0, COUNTIF($A$1:A3, 'Census Data'!$B$2:$B$504), 0))} -> Arizona | B4: =ROUND(AVERAGEIF('Census Data'!B$1:B$1004,A4,'Census Data'!S$1:S$1004),0) -> 40 | C4: =VLOOKUP(B4,'Grading Scale'!$A$2:$B$14, 2) -> F
A5: {=INDEX('Census Data'!$B$2:$B$504, MATCH(0, COUNTIF($A$1:A4, 'Census Data'!$B$2:$B$504), 0))} -> Arkansas | B5: =ROUND(AVERAGEIF('Census Data'!B$1:B$1004,A5,'Census Data'!S$1:S$1004),0) -> 46 | C5: =VLOOKUP(B5,'Grading Scale'!$A$2:$B$14, 2) -> F
A6: {=INDEX('Census Data'!$B$2:$B$504, MATCH(0, COUNTIF($A$1:A5, 'Census Data'!$B$2:$B$504), 0))} -> California | B6: =ROUND(AVERAGEIF('Census Data'!B$1:B$1004,A6,'Census Data'!S$1:S$1004),0) -> 42 | C6: =VLOOKUP(B6,'Grading Scale'!$A$2:$B$14, 2) -> F | D6: http://data.ca.gov/
A7: {=INDEX('Census Data'!$B$2:$B$504, MATCH(0, COUNTIF($A$1:A6, 'Census Data'!$B$2:$B$504), 0))} -> Colorado | B7: =ROUND(AVERAGEIF('Census Data'!B$1:B$1004,A7,'Census Data'!S$1:S$1004),0) -> 57 | C7: =VLOOKUP(B7,'Grading Scale'!$A$2:$B$14, 2) -> F | D7: https://data.colorado.gov/
A8: {=INDEX('Census Data'!$B$2:$B$504, MATCH(0, COUNTIF($A$1:A7, 'Census Data'!$B$2:$B$504), 0))} -> Connecticut | B8: =ROUND(AVERAGEIF('Census Data'!B$1:B$1004,A8,'Census Data'!S$1:S$1004),0) -> 84 | C8: =VLOOKUP(B8,'Grading Scale'!$A$2:$B$14, 2) -> B | D8: https://data.ct.gov/
A9: {=INDEX('Census Data'!$B$2:$B$504, MATCH(0, COUNTIF($A$1:A8, 'Census Data'!$B$2:$B$504), 0))} -> Delaware | B9: =ROUND(AVERAGEIF('Census Data'!B$1:B$1004,A9,'Census Data'!S$1:S$1004),0) -> 48 | C9: =VLOOKUP(B9,'Grading Scale'!$A$2:$B$14, 2) -> F | D9: https://delaware.gov/topics/data
A10: {=INDEX('Census Data'!$B$2:$B$504, MATCH(0, COUNTIF($A$1:A9, 'Census Data'!$B$2:$B$504), 0))} -> Florida | B10: =ROUND(AVERAGEIF('Census Data'!B$1:B$1004,A10,'Census Data'!S$1:S$1004),0) -> 43 | C10: =VLOOKUP(B10,'Grading Scale'!$A$2:$B$14, 2) -> F
A11: {=INDEX('Census Data'!$B$2:$B$504, MATCH(0, COUNTIF($A$1:A10, 'Census Data'!$B$2:$B$504), 0))} -> Georgia | B11: =ROUND(AVERAGEIF('Census Data'!B$1:B$1004,A11,'Census Data'!S$1:S$1004),0) -> 39 | C11: =VLOOKUP(B11,'Grading Scale'!$A$2:$B$14, 2) -> F | D11: http://www.open.georgia.gov/
A12: {=INDEX('Census Data'!$B$2:$B$504, MATCH(0, COUNTIF($A$1:A11, 'Census Data'!$B$2:$B$504), 0))} -> Hawaii | B12: =ROUND(AVERAGEIF('Census Data'!B$1:B$1004,A12,'Census Data'!S$1:S$1004),0) -> 34 | C12: =VLOOKUP(B12,'Grading Scale'!$A$2:$B$14, 2) -> F | D12: https://data.hawaii.gov/
A13: {=INDEX('Census Data'!$B$2:$B$504, MATCH(0, COUNTIF($A$1:A12, 'Census Data'!$B$2:$B$504), 0))} -> Idaho | B13: =ROUND(AVERAGEIF('Census Data'!B$1:B$1004,A13,'Census Data'!S$1:S$1004),0) -> 21 | C13: =VLOOKUP(B13,'Grading Scale'!$A$2:$B$14, 2) -> F
A14: {=INDEX('Census Data'!$B$2:$B$504, MATCH(0, COUNTIF($A$1:A13, 'Census Data'!$B$2:$B$504), 0))} -> Illinois | B14: =ROUND(AVERAGEIF('Census Data'!B$1:B$1004,A14,'Census Data'!S$1:S$1004),0) -> 29 | C14: =VLOOKUP(B14,'Grading Scale'!$A$2:$B$14, 2) -> F | D14: https://data.illinois.gov/
A15: {=INDEX('Census Data'!$B$2:$B$504, MATCH(0, COUNTIF($A$1:A14, 'Census Data'!$B$2:$B$504), 0))} -> Indiana | B15: =ROUND(AVERAGEIF('Census Data'!B$1:B$1004,A15,'Census Data'!S$1:S$1004),0) -> 56 | C15: =VLOOKUP(B15,'Grading Scale'!$A$2:$B$14, 2) -> F
A16: {=INDEX('Census Data'!$B$2:$B$504, MATCH(0, COUNTIF($A$1:A15, 'Census Data'!$B$2:$B$504), 0))} -> Iowa | B16: =ROUND(AVERAGEIF('Census Data'!B$1:B$1004,A16,'Census Data'!S$1:S$1004),0) -> 61 | C16: =VLOOKUP(B16,'Grading Scale'!$A$2:$B$14, 2) -> D− | D16: https://data.iowa.gov/
A17: {=INDEX('Census Data'!$B$2:$B$504, MATCH(0, COUNTIF($A$1:A16, 'Census Data'!$B$2:$B$504), 0))} -> Kansas | B17: =ROUND(AVERAGEIF('Census Data'!B$1:B$1004,A17,'Census Data'!S$1:S$1004),0) -> 37 | C17: =VLOOKUP(B17,'Grading Scale'!$A$2:$B$14, 2) -> F
A18: {=INDEX('Census Data'!$B$2:$B$504, MATCH(0, COUNTIF($A$1:A17, 'Census Data'!$B$2:$B$504), 0))} -> Kentucky | B18: =ROUND(AVERAGEIF('Census Data'!B$1:B$1004,A18,'Census Data'!S$1:S$1004),0) -> 47 | C18: =VLOOKUP(B18,'Grading Scale'!$A$2:$B$14, 2) -> F
A19: {=INDEX('Census Data'!$B$2:$B$504, MATCH(0, COUNTIF($A$1:A18, 'Census Data'!$B$2:$B$504), 0))} -> Louisiana | B19: =ROUND(AVERAGEIF('Census Data'!B$1:B$1004,A19,'Census Data'!S$1:S$1004),0) -> 51 | C19: =VLOOKUP(B19,'Grading Scale'!$A$2:$B$14, 2) -> F
A20: {=INDEX('Census Data'!$B$2:$B$504, MATCH(0, COUNTIF($A$1:A19, 'Census Data'!$B$2:$B$504), 0))} -> Maine | B20: =ROUND(AVERAGEIF('Census Data'!B$1:B$1004,A20,'Census Data'!S$1:S$1004),0) -> 47 | C20: =VLOOKUP(B20,'Grading Scale'!$A$2:$B$14, 2) -> F | D20: https://data.maine.gov/
A21: {=INDEX('Census Data'!$B$2:$B$504, MATCH(0, COUNTIF($A$1:A20, 'Census Data'!$B$2:$B$504), 0))} -> Maryland | B21: =ROUND(AVERAGEIF('Census Data'!B$1:B$1004,A21,'Census Data'!S$1:S$1004),0) -> 58 | C21: =VLOOKUP(B21,'Grading Scale'!$A$2:$B$14, 2) -> F | D21: https://data.md.gov/
A22: {=INDEX('Census Data'!$B$2:$B$504, MATCH(0, COUNTIF($A$1:A21, 'Census Data'!$B$2:$B$504), 0))} -> Massachusetts | B22: =ROUND(AVERAGEIF('Census Data'!B$1:B$1004,A22,'Census Data'!S$1:S$1004),0) -> 53 | C22: =VLOOKUP(B22,'Grading Scale'!$A$2:$B$14, 2) -> F | D22: http://www.mass.gov/opendata/
A23: {=INDEX('Census Data'!$B$2:$B$504, MATCH(0, COUNTIF($A$1:A22, 'Census Data'!$B$2:$B$504), 0))} -> Michigan | B23: =ROUND(AVERAGEIF('Census Data'!B$1:B$1004,A23,'Census Data'!S$1:S$1004),0) -> 36 | C23: =VLOOKUP(B23,'Grading Scale'!$A$2:$B$14, 2) -> F | D23: https://data.michigan.gov/
A24: {=INDEX('Census Data'!$B$2:$B$504, MATCH(0, COUNTIF($A$1:A23, 'Census Data'!$B$2:$B$504), 0))} -> Minnesota | B24: =ROUND(AVERAGEIF('Census Data'!B$1:B$1004,A24,'Census Data'!S$1:S$1004),0) -> 42 | C24: =VLOOKUP(B24,'Grading Scale'!$A$2:$B$14, 2) -> F | D24: http://www.state.mn.us/opendata/
A25: {=INDEX('Census Data'!$B$2:$B$504, MATCH(0, COUNTIF($A$1:A24, 'Census Data'!$B$2:$B$504), 0))} -> Mississippi | B25: =ROUND(AVERAGEIF('Census Data'!B$1:B$1004,A25,'Census Data'!S$1:S$1004),0) -> 37 | C25: =VLOOKUP(B25,'Grading Scale'!$A$2:$B$14, 2) -> F | D25: https://data.mo.gov/
A26: {=INDEX('Census Data'!$B$2:$B$504, MATCH(0, COUNTIF($A$1:A25, 'Census Data'!$B$2:$B$504), 0))} -> Missouri | B26: =ROUND(AVERAGEIF('Census Data'!B$1:B$1004,A26,'Census Data'!S$1:S$1004),0) -> 46 | C26: =VLOOKUP(B26,'Grading Scale'!$A$2:$B$14, 2) -> F | D26: http://data.mt.gov/
A27: {=INDEX('Census Data'!$B$2:$B$504, MATCH(0, COUNTIF($A$1:A26, 'Census Data'!$B$2:$B$504), 0))} -> Montana | B27: =ROUND(AVERAGEIF('Census Data'!B$1:B$1004,A27,'Census Data'!S$1:S$1004),0) -> 66 | C27: =VLOOKUP(B27,'Grading Scale'!$A$2:$B$14, 2) -> D
A28: {=INDEX('Census Data'!$B$2:$B$504, MATCH(0, COUNTIF($A$1:A27, 'Census Data'!$B$2:$B$504), 0))} -> Nebraska | B28: =ROUND(AVERAGEIF('Census Data'!B$1:B$1004,A28,'Census Data'!S$1:S$1004),0) -> 46 | C28: =VLOOKUP(B28,'Grading Scale'!$A$2:$B$14, 2) -> F
A29: {=INDEX('Census Data'!$B$2:$B$504, MATCH(0, COUNTIF($A$1:A28, 'Census Data'!$B$2:$B$504), 0))} -> Nevada | B29: =ROUND(AVERAGEIF('Census Data'!B$1:B$1004,A29,'Census Data'!S$1:S$1004),0) -> 43 | C29: =VLOOKUP(B29,'Grading Scale'!$A$2:$B$14, 2) -> F | D29: http://data.nh.gov/ | E29: Kentucky claims copyright over nearly all of their datasets (with a copyright statement in the footer), despite that they almost certainly lack the legal authority to do so. Also, their open data site is really a late-'00s-style open finances site, not an open data repository in the modern sense.
A30: {=INDEX('Census Data'!$B$2:$B$504, MATCH(0, COUNTIF($A$1:A29, 'Census Data'!$B$2:$B$504), 0))} -> New Hampshire | B30: =ROUND(AVERAGEIF('Census Data'!B$1:B$1004,A30,'Census Data'!S$1:S$1004),0) -> 53 | C30: =VLOOKUP(B30,'Grading Scale'!$A$2:$B$14, 2) -> F | D30: https://data.nj.gov/
A31: {=INDEX('Census Data'!$B$2:$B$504, MATCH(0, COUNTIF($A$1:A30, 'Census Data'!$B$2:$B$504), 0))} -> New Jersey | B31: =ROUND(AVERAGEIF('Census Data'!B$1:B$1004,A31,'Census Data'!S$1:S$1004),0) -> 43 | C31: =VLOOKUP(B31,'Grading Scale'!$A$2:$B$14, 2) -> F
A32: {=INDEX('Census Data'!$B$2:$B$504, MATCH(0, COUNTIF($A$1:A31, 'Census Data'!$B$2:$B$504), 0))} -> New Mexico | B32: =ROUND(AVERAGEIF('Census Data'!B$1:B$1004,A32,'Census Data'!S$1:S$1004),0) -> 40 | C32: =VLOOKUP(B32,'Grading Scale'!$A$2:$B$14, 2) -> F | D32: https://data.ny.gov/ | E32: Census is inaccurate pending modification of the census software to allow scoring of the legislature. (It keeps its data on two separate sites, one for each chamber.)
A33: {=INDEX('Census Data'!$B$2:$B$504, MATCH(0, COUNTIF($A$1:A32, 'Census Data'!$B$2:$B$504), 0))} -> New York | B33: =ROUND(AVERAGEIF('Census Data'!B$1:B$1004,A33,'Census Data'!S$1:S$1004),0) -> 74 | C33: =VLOOKUP(B33,'Grading Scale'!$A$2:$B$14, 2) -> C
A34: {=INDEX('Census Data'!$B$2:$B$504, MATCH(0, COUNTIF($A$1:A33, 'Census Data'!$B$2:$B$504), 0))} -> North Carolina | B34: =ROUND(AVERAGEIF('Census Data'!B$1:B$1004,A34,'Census Data'!S$1:S$1004),0) -> 56 | C34: =VLOOKUP(B34,'Grading Scale'!$A$2:$B$14, 2) -> F
A35: {=INDEX('Census Data'!$B$2:$B$504, MATCH(0, COUNTIF($A$1:A34, 'Census Data'!$B$2:$B$504), 0))} -> North Dakota | B35: =ROUND(AVERAGEIF('Census Data'!B$1:B$1004,A35,'Census Data'!S$1:S$1004),0) -> 28 | C35: =VLOOKUP(B35,'Grading Scale'!$A$2:$B$14, 2) -> F
A36: {=INDEX('Census Data'!$B$2:$B$504, MATCH(0, COUNTIF($A$1:A35, 'Census Data'!$B$2:$B$504), 0))} -> Ohio | B36: =ROUND(AVERAGEIF('Census Data'!B$1:B$1004,A36,'Census Data'!S$1:S$1004),0) -> 67 | C36: =VLOOKUP(B36,'Grading Scale'!$A$2:$B$14, 2) -> D+ | D36: https://data.ok.gov/
A37: {=INDEX('Census Data'!$B$2:$B$504, MATCH(0, COUNTIF($A$1:A36, 'Census Data'!$B$2:$B$504), 0))} -> Oklahoma | B37: =ROUND(AVERAGEIF('Census Data'!B$1:B$1004,A37,'Census Data'!S$1:S$1004),0) -> 58 | C37: =VLOOKUP(B37,'Grading Scale'!$A$2:$B$14, 2) -> F | D37: https://data.oregon.gov/
A38: {=INDEX('Census Data'!$B$2:$B$504, MATCH(0, COUNTIF($A$1:A37, 'Census Data'!$B$2:$B$504), 0))} -> Oregon | B38: =ROUND(AVERAGEIF('Census Data'!B$1:B$1004,A38,'Census Data'!S$1:S$1004),0) -> 51 | C38: =VLOOKUP(B38,'Grading Scale'!$A$2:$B$14, 2) -> F
A39: {=INDEX('Census Data'!$B$2:$B$504, MATCH(0, COUNTIF($A$1:A38, 'Census Data'!$B$2:$B$504), 0))} -> Pennsylvania | B39: =ROUND(AVERAGEIF('Census Data'!B$1:B$1004,A39,'Census Data'!S$1:S$1004),0) -> 39 | C39: =VLOOKUP(B39,'Grading Scale'!$A$2:$B$14, 2) -> F | D39: https://data.pr.gov/
A40: {=INDEX('Census Data'!$B$2:$B$504, MATCH(0, COUNTIF($A$1:A39, 'Census Data'!$B$2:$B$504), 0))} -> Puerto Rico | B40: =ROUND(AVERAGEIF('Census Data'!B$1:B$1004,A40,'Census Data'!S$1:S$1004),0) -> 43 | C40: =VLOOKUP(B40,'Grading Scale'!$A$2:$B$14, 2) -> F | D40: http://www.ri.gov/data/
...
